<mujoco model="JAXON_JVRC">
    <compiler angle="radian" />
    <size njmax="500" nconmax="100" />
    <default>
        <joint damping="0.1"/>
        <motor ctrlrange="-.4 4." ctrllimited="true"/>
    </default>
    <contact>
        <exclude body1="CHEST_LINK0" body2="CHEST_LINK1"/>
        <exclude body1="CHEST_LINK1" body2="CHEST_LINK2"/>
        <exclude body1="CHEST_LINK2" body2="HEAD_LINK0"/>
        <exclude body1="HEAD_LINK0" body2="HEAD_LINK1"/>
        <exclude body1="HEAD_LINK1" body2="RANGE_LINK"/>
        <exclude body1="CHEST_LINK2" body2="LARM_LINK0"/>
        <exclude body1="LARM_LINK0" body2="LARM_LINK1"/>
        <exclude body1="LARM_LINK1" body2="LARM_LINK2"/>
        <exclude body1="LARM_LINK2" body2="LARM_LINK3"/>
        <exclude body1="LARM_LINK3" body2="LARM_LINK4"/>
        <exclude body1="LARM_LINK4" body2="LARM_LINK5"/>
        <exclude body1="LARM_LINK5" body2="LARM_LINK6"/>
        <exclude body1="LARM_LINK6" body2="LARM_LINK7"/>
        <exclude body1="LARM_LINK7" body2="LARM_FINGER0"/>
        <exclude body1="LARM_LINK7" body2="LARM_FINGER1"/>
        <exclude body1="RARM_LINK0" body2="RARM_LINK1"/>
        <exclude body1="RARM_LINK1" body2="RARM_LINK2"/>
        <exclude body1="RARM_LINK2" body2="RARM_LINK3"/>
        <exclude body1="RARM_LINK3" body2="RARM_LINK4"/>
        <exclude body1="RARM_LINK4" body2="RARM_LINK5"/>
        <exclude body1="RARM_LINK5" body2="RARM_LINK6"/>
        <exclude body1="RARM_LINK6" body2="RARM_LINK7"/>
        <exclude body1="RARM_LINK7" body2="RARM_FINGER0"/>
        <exclude body1="RARM_LINK7" body2="RARM_FINGER1"/>
        <exclude body1="LLEG_LINK0" body2="LLEG_LINK1"/>
        <exclude body1="LLEG_LINK1" body2="LLEG_LINK2"/>
        <exclude body1="LLEG_LINK2" body2="LLEG_LINK3"/>
        <exclude body1="LLEG_LINK3" body2="LLEG_LINK4"/>
        <exclude body1="LLEG_LINK4" body2="LLEG_LINK5"/>
        <exclude body1="RLEG_LINK0" body2="RLEG_LINK1"/>
        <exclude body1="RLEG_LINK1" body2="RLEG_LINK2"/>
        <exclude body1="RLEG_LINK2" body2="RLEG_LINK3"/>
        <exclude body1="RLEG_LINK3" body2="RLEG_LINK4"/>
        <exclude body1="RLEG_LINK4" body2="RLEG_LINK5"/>
    </contact>
    <asset>
        <mesh name="BODY_mesh" file="BODY_mesh.stl" />
        <mesh name="CHEST_LINK0_mesh" file="CHEST_LINK0_mesh.stl" />
        <mesh name="CHEST_LINK1_mesh" file="CHEST_LINK1_mesh.stl" />
        <mesh name="CHEST_LINK2_mesh" file="CHEST_LINK2_mesh.stl" />
        <mesh name="HEAD_LINK0_mesh" file="HEAD_LINK0_mesh.stl" />
        <mesh name="HEAD_LINK1_mesh" file="HEAD_LINK1_mesh.stl" />
        <mesh name="RANGE_LINK_mesh" file="RANGE_LINK_mesh.stl" />
        <mesh name="LARM_LINK0_mesh" file="LARM_LINK0_mesh.stl" />
        <mesh name="LARM_LINK1_mesh" file="LARM_LINK1_mesh.stl" />
        <mesh name="LARM_LINK2_mesh" file="LARM_LINK2_mesh.stl" />
        <mesh name="LARM_LINK3_mesh" file="LARM_LINK3_mesh.stl" />
        <mesh name="LARM_LINK4_mesh" file="LARM_LINK4_mesh.stl" />
        <mesh name="LARM_LINK5_mesh" file="LARM_LINK5_mesh.stl" />
        <mesh name="LARM_LINK6_mesh" file="LARM_LINK6_mesh.stl" />
        <mesh name="LARM_LINK7_mesh" file="LARM_LINK7_mesh.stl" />
        <mesh name="LARM_FINGER0_mesh" file="LARM_FINGER0_mesh.stl" />
        <mesh name="LARM_FINGER1_mesh" file="LARM_FINGER1_mesh.stl" />
        <mesh name="RARM_LINK0_mesh" file="RARM_LINK0_mesh.stl" />
        <mesh name="RARM_LINK1_mesh" file="RARM_LINK1_mesh.stl" />
        <mesh name="RARM_LINK2_mesh" file="RARM_LINK2_mesh.stl" />
        <mesh name="RARM_LINK3_mesh" file="RARM_LINK3_mesh.stl" />
        <mesh name="RARM_LINK4_mesh" file="RARM_LINK4_mesh.stl" />
        <mesh name="RARM_LINK5_mesh" file="RARM_LINK5_mesh.stl" />
        <mesh name="RARM_LINK6_mesh" file="RARM_LINK6_mesh.stl" />
        <mesh name="RARM_LINK7_mesh" file="RARM_LINK7_mesh.stl" />
        <mesh name="RARM_FINGER0_mesh" file="RARM_FINGER0_mesh.stl" />
        <mesh name="RARM_FINGER1_mesh" file="RARM_FINGER1_mesh.stl" />
        <mesh name="LLEG_LINK0_mesh" file="LLEG_LINK0_mesh.stl" />
        <mesh name="LLEG_LINK1_mesh" file="LLEG_LINK1_mesh.stl" />
        <mesh name="LLEG_LINK2_mesh" file="LLEG_LINK2_mesh.stl" />
        <mesh name="LLEG_LINK3_mesh" file="LLEG_LINK3_mesh.stl" />
        <mesh name="LLEG_LINK4_mesh" file="LLEG_LINK4_mesh.stl" />
        <mesh name="LLEG_LINK5_mesh" file="LLEG_LINK5_mesh.stl" />
        <mesh name="RLEG_LINK0_mesh" file="RLEG_LINK0_mesh.stl" />
        <mesh name="RLEG_LINK1_mesh" file="RLEG_LINK1_mesh.stl" />
        <mesh name="RLEG_LINK2_mesh" file="RLEG_LINK2_mesh.stl" />
        <mesh name="RLEG_LINK3_mesh" file="RLEG_LINK3_mesh.stl" />
        <mesh name="RLEG_LINK4_mesh" file="RLEG_LINK4_mesh.stl" />
        <mesh name="RLEG_LINK5_mesh" file="RLEG_LINK5_mesh.stl" />
    </asset>
    <worldbody>
        <geom name="plane" type="plane" size="1 1 .1" pos="0 0 0" rgba="0 0 1 1"/>
        <body name="jaxon" pos="0 0 1.05">
            <joint name="jaxon_free_joint" type="free"/>
            <geom pos="0 0 1.0225" type="mesh" mesh="BODY_mesh" />
            <body name="CHEST_LINK0" pos="0.006 0 0.128">
                <inertial pos="-0.0084 0.00137 0.01359" mass="0.866" diaginertia="0.00125384 0.00123407 0.000677392" />
                <joint name="CHEST_JOINT0" pos="0 0 0" axis="1 0 0" limited="true" range="-0.198551 0.198551" damping="0.2" />
                <geom pos="0.006 0 0.128" type="mesh" mesh="CHEST_LINK0_mesh" />
                <body name="CHEST_LINK1" pos="0 0 0.025">
                    <inertial pos="-0.111697 0.0039 0.03652" quat="0.0099888 0.65884 -0.00254466 0.752212" mass="18.23" diaginertia="0.482918 0.418072 0.181216" />
                    <joint name="CHEST_JOINT1" pos="0 0 0" axis="0 1 0" limited="true" range="-0.0349066 0.610865" damping="0.2" />
                    <geom pos="0 0 0.025" type="mesh" mesh="CHEST_LINK1_mesh" />
                    <body name="CHEST_LINK2" pos="0 0 0.3085">
                        <inertial pos="-0.13693 -0.00113 -0.05796" quat="0.396766 0.605351 0.509194 0.46567" mass="31.33" diaginertia="1.09683 1.06131 0.473474" />
                        <joint name="CHEST_JOINT2" pos="0 0 0" axis="0 0 1" limited="true" range="-1.0566 1.0566" damping="0.2" />
                        <geom pos="0 0 0.3085" type="mesh" mesh="CHEST_LINK2_mesh" />
                        <body name="HEAD_LINK0" pos="-0.015 0 0.0835">
                            <inertial pos="-0.01227 3e-05 0.03231" quat="0.707107 0 0 0.707107" mass="1.086" diaginertia="0.0035 0.0031 0.00119" />
                            <joint name="HEAD_JOINT0" pos="0 0 0" axis="0 0 1" limited="true" range="-0.575959 0.541052" damping="0.2" />
                            <geom pos="-0.015 0 0.0835" type="mesh" mesh="HEAD_LINK0_mesh" />
                            <body name="HEAD_LINK1" pos="0 0 0.102">
                                <inertial pos="0.042 0.004 0.058" quat="0.710144 0.293512 0.236094 0.594816" mass="4.274" diaginertia="0.0402075 0.0386678 0.0321897" />
                                <joint name="HEAD_JOINT1" pos="0 0 0" axis="0 1 0" limited="true" range="-0.575959 0.698132" damping="0.2" />
                                <geom pos="0 0 0.102" type="mesh" mesh="HEAD_LINK1_mesh" />
                                <body name="RANGE_LINK" pos="0.0559 0 0.14425">
                                    <inertial pos="0.03 0 0" mass="0.4" diaginertia="0.00024 0.00024 0.00024" />
                                    <joint name="motor_joint" pos="0 0 0" axis="1 0 0" limited="true" range="-3.14159 3.14159" damping="0.2" />
                                    <geom pos="0.0559 0 0.14425" type="mesh" mesh="RANGE_LINK_mesh" />
                                </body>
                            </body>
                        </body>
                        <body name="LARM_LINK0" pos="0 0.0875 0">
                            <inertial pos="-0.01745 0.00887 -0.00015" quat="0.5 0.5 -0.5 0.5" mass="1.048" diaginertia="0.00355486 0.0029762 0.00235085" />
                            <joint name="LARM_JOINT0" pos="0 0 0" axis="0 0 1" limited="true" range="-1.4208 0.144751" damping="0.2" />
                            <geom pos="0 0.0875 0" type="mesh" mesh="LARM_LINK0_mesh" />
                            <body name="LARM_LINK1" pos="0 0.07275 0">
                                <inertial pos="0.00011 0.01799 0.00288" quat="0.707107 0.707107 0 0" mass="0.298" diaginertia="0.000412035 0.000376771 0.000251611" />
                                <joint name="LARM_JOINT1" pos="0 0 0" axis="0 1 0" limited="true" range="-3.14159 3.14159" damping="0.2" />
                                <geom pos="0 0.07275 0" type="mesh" mesh="LARM_LINK1_mesh" />
                                <body name="LARM_LINK2" pos="0 0.057 0">
                                    <inertial pos="0.00845 0.00671 -0.0881" quat="0.707107 0 0 0.707107" mass="2.168" diaginertia="0.0133751 0.0127408 0.00460362" />
                                    <joint name="LARM_JOINT2" pos="0 0 0" axis="1 0 0" limited="true" range="0.2762 3.14159" damping="0.2" />
                                    <geom pos="0 0.057 0" type="mesh" mesh="LARM_LINK2_mesh" />
                                    <body name="LARM_LINK3" pos="0 0 -0.1965">
                                        <inertial pos="0.01393 4e-05 -0.07574" quat="0.707107 0 0 0.707107" mass="1.315" diaginertia="0.0055237 0.00451716 0.00217053" />
                                        <joint name="LARM_JOINT3" pos="0 0 0" axis="0 0 1" limited="true" range="-3.14159 3.14159" damping="0.2" />
                                        <geom pos="0 0 -0.1965" type="mesh" mesh="LARM_LINK3_mesh" />
                                        <body name="LARM_LINK4" pos="0 0 -0.126">
                                            <inertial pos="3e-05 0.00551 -0.0426" mass="1.641" diaginertia="0.00665559 0.00598857 0.00288237" />
                                            <joint name="LARM_JOINT4" pos="0 0 0" axis="0 1 0" limited="true" range="-2.19006 1.0472" damping="0.2" />
                                            <geom pos="0 0 -0.126" type="mesh" mesh="LARM_LINK4_mesh" />
                                            <body name="LARM_LINK5" pos="0 0 -0.1275">
                                                <inertial pos="0.01271 2e-05 -0.08415" quat="0.707107 0 0 0.707107" mass="1.305" diaginertia="0.00624028 0.00533939 0.00205604" />
                                                <joint name="LARM_JOINT5" pos="0 0 0" axis="0 0 1" limited="true" range="-3.14159 3.14159" damping="0.2" />
                                                <geom pos="0 0 -0.1275" type="mesh" mesh="LARM_LINK5_mesh" />
                                                <body name="LARM_LINK6" pos="0 0 -0.146">
                                                    <inertial pos="0.00013 0.01427 0.00188" mass="0.505" diaginertia="0.000901789 0.000626727 0.000593753" />
                                                    <joint name="LARM_JOINT6" pos="0 0 0" axis="1 0 0" limited="true" range="-1.54494 1.5708" damping="0.2" />
                                                    <geom pos="0 0 -0.146" type="mesh" mesh="LARM_LINK6_mesh" />
                                                    <body name="LARM_LINK7" pos="0 0 -0.04">
                                                        <inertial pos="0 0 -0.085" quat="0.999313 0.0370448 -0.000511674 -0.000402099" mass="2.257" diaginertia="0.020752 0.0198372 0.0130518" />
                                                        <joint name="LARM_JOINT7" pos="0 0 0" axis="0 1 0" limited="true" range="-1.41372 1.0472" damping="0.2" />
                                                        <geom pos="0 0 -0.04" type="mesh" mesh="LARM_LINK7_mesh" />
                                                        <body name="LARM_FINGER0" pos="0 -0.06 -0.1725" quat="9.38184e-07 0.707108 9.38187e-07 -0.707105">
                                                            <inertial pos="0.077 0.0138 0" quat="0.0449183 0.705679 -0.0449183 0.705679" mass="0.15" diaginertia="0.00128 0.00126494 2.45646e-05" />
                                                            <joint name="LARM_F_JOINT0" pos="0 0 0" axis="0 0 1" limited="true" range="-1.39626 0.610865" damping="0.2" />
                                                            <geom pos="0 -0.06 -0.1725" quat="9.38184e-07 0.707108 9.38187e-07 -0.707105" type="mesh" mesh="LARM_FINGER0_mesh" />
                                                        </body>
                                                        <body name="LARM_FINGER1" pos="0 0.06 -0.1725" quat="9.38184e-07 0.707108 9.38187e-07 -0.707105">
                                                            <inertial pos="0.077 0.0138 0" quat="0.0449183 0.705679 -0.0449183 0.705679" mass="0.3" diaginertia="0.00128 0.00126494 2.45646e-05" />
                                                            <joint name="LARM_F_JOINT1" pos="0 0 0" axis="0 0 1" limited="true" range="-0.610865 1.39626" damping="0.2" />
                                                            <geom pos="0 0.06 -0.1725" quat="9.38184e-07 0.707108 9.38187e-07 -0.707105" type="mesh" mesh="LARM_FINGER1_mesh" />
                                                        </body>
                                                    </body>
                                                </body>
                                            </body>
                                        </body>
                                    </body>
                                </body>
                            </body>
                        </body>
                        <body name="RARM_LINK0" pos="0 -0.0875 0">
                            <inertial pos="-0.01745 -0.00887 -0.00015" quat="0.5 0.5 -0.5 0.5" mass="1.048" diaginertia="0.00355486 0.0029762 0.00235085" />
                            <joint name="RARM_JOINT0" pos="0 0 0" axis="0 0 1" limited="true" range="-0.144751 1.4208" damping="0.2" />
                            <geom pos="0 -0.0875 0" type="mesh" mesh="RARM_LINK0_mesh" />
                            <body name="RARM_LINK1" pos="0 -0.07275 0">
                                <inertial pos="0.00011 -0.01799 0.00288" quat="0.707107 0.707107 0 0" mass="0.298" diaginertia="0.000412035 0.000376771 0.000251611" />
                                <joint name="RARM_JOINT1" pos="0 0 0" axis="0 1 0" limited="true" range="-3.14159 3.14159" damping="0.2" />
                                <geom pos="0 -0.07275 0" type="mesh" mesh="RARM_LINK1_mesh" />
                                <body name="RARM_LINK2" pos="0 -0.057 0">
                                    <inertial pos="0.00845 -0.00671 -0.0881" quat="0.707107 0 0 0.707107" mass="2.168" diaginertia="0.0133751 0.0127408 0.00460362" />
                                    <joint name="RARM_JOINT2" pos="0 0 0" axis="1 0 0" limited="true" range="-3.14159 -0.2762" damping="0.2" />
                                    <geom pos="0 -0.057 0" type="mesh" mesh="RARM_LINK2_mesh" />
                                    <body name="RARM_LINK3" pos="0 0 -0.1965">
                                        <inertial pos="0.01393 -4e-05 -0.07574" quat="0.707107 0 0 0.707107" mass="1.315" diaginertia="0.0055237 0.00451716 0.00217053" />
                                        <joint name="RARM_JOINT3" pos="0 0 0" axis="0 0 1" limited="true" range="-3.14159 3.14159" damping="0.2" />
                                        <geom pos="0 0 -0.1965" type="mesh" mesh="RARM_LINK3_mesh" />
                                        <body name="RARM_LINK4" pos="0 0 -0.126">
                                            <inertial pos="3e-05 -0.00551 -0.0426" mass="1.641" diaginertia="0.00665559 0.00598857 0.00288237" />
                                            <joint name="RARM_JOINT4" pos="0 0 0" axis="0 1 0" limited="true" range="-2.19006 1.0472" damping="0.2" />
                                            <geom pos="0 0 -0.126" type="mesh" mesh="RARM_LINK4_mesh" />
                                            <body name="RARM_LINK5" pos="0 0 -0.1275">
                                                <inertial pos="0.01271 -2e-05 -0.08415" quat="0.707107 0 0 0.707107" mass="1.305" diaginertia="0.00624028 0.00533939 0.00205604" />
                                                <joint name="RARM_JOINT5" pos="0 0 0" axis="0 0 1" limited="true" range="-3.14159 3.14159" damping="0.2" />
                                                <geom pos="0 0 -0.1275" type="mesh" mesh="RARM_LINK5_mesh" />
                                                <body name="RARM_LINK6" pos="0 0 -0.146">
                                                    <inertial pos="0.00013 -0.01427 0.00188" mass="0.505" diaginertia="0.000901789 0.000626727 0.000593753" />
                                                    <joint name="RARM_JOINT6" pos="0 0 0" axis="1 0 0" limited="true" range="-1.5708 1.54494" damping="0.2" />
                                                    <geom pos="0 0 -0.146" type="mesh" mesh="RARM_LINK6_mesh" />
                                                    <body name="RARM_LINK7" pos="0 0 -0.04">
                                                        <inertial pos="0 0 -0.085" quat="0.999313 -0.037044 0.000551637 0.001013" mass="2.257" diaginertia="0.020752 0.0198372 0.0130518" />
                                                        <joint name="RARM_JOINT7" pos="0 0 0" axis="0 1 0" limited="true" range="-1.41372 1.0472" damping="0.2" />
                                                        <geom pos="0 0 -0.04" type="mesh" mesh="RARM_LINK7_mesh" />
                                                        <body name="RARM_FINGER0" pos="0 0.06 -0.1725" quat="0.707105 0 0.707108 0">
                                                            <inertial pos="0.077 0.0138 0" quat="0.0449183 0.705679 -0.0449183 0.705679" mass="0.15" diaginertia="0.00128 0.00126494 2.45646e-05" />
                                                            <joint name="RARM_F_JOINT0" pos="0 0 0" axis="0 0 1" limited="true" range="-1.39626 0.610865" damping="0.2" />
                                                            <geom pos="0 0.06 -0.1725" quat="0.707105 0 0.707108 0" type="mesh" mesh="RARM_FINGER0_mesh" />
                                                        </body>
                                                        <body name="RARM_FINGER1" pos="0 -0.06 -0.1725" quat="0.707105 0 0.707108 0">
                                                            <inertial pos="0.077 0.0138 0" quat="0.0449183 0.705679 -0.0449183 0.705679" mass="0.3" diaginertia="0.00128 0.00126494 2.45646e-05" />
                                                            <joint name="RARM_F_JOINT1" pos="0 0 0" axis="0 0 1" limited="true" range="-0.610865 1.39626" damping="0.2" />
                                                            <geom pos="0 -0.06 -0.1725" quat="0.707105 0 0.707108 0" type="mesh" mesh="RARM_FINGER1_mesh" />
                                                        </body>
                                                    </body>
                                                </body>
                                            </body>
                                        </body>
                                    </body>
                                </body>
                            </body>
                        </body>
                    </body>
                </body>
            </body>
            <body name="LLEG_LINK0" pos="0 0.1 0.0095">
                <inertial pos="-0.02299 -0.00588 -0.07031" quat="0.908703 0.283036 -0.0102762 -0.306665" mass="2.915" diaginertia="0.00999933 0.00999641 0.00998966" />
                <joint name="LLEG_JOINT0" pos="0 0 0" axis="0 0 1" limited="true" range="-1.0972 1.02662" damping="0.2" />
                <geom pos="0 0.1 0.0095" type="mesh" mesh="LLEG_LINK0_mesh" />
                <body name="LLEG_LINK1" pos="0 0 -0.122">
                    <inertial pos="-0.00441 0.00696 -0.00694" quat="0.5 0.5 -0.5 0.5" mass="1.199" diaginertia="0.00343603 0.00299879 0.00179963" />
                    <joint name="LLEG_JOINT1" pos="0 0 0" axis="1 0 0" limited="true" range="-0.523599 0.725029" damping="0.2" />
                    <geom pos="0 0 -0.122" type="mesh" mesh="LLEG_LINK1_mesh" />
                    <body name="LLEG_LINK2" pos="0 0 -0.01">
                        <inertial pos="0.00658 0.03431 -0.18864" quat="0.850561 -0.0272808 -0.0126242 0.525016" mass="5.783" diaginertia="0.110101 0.110013 0.00999652" />
                        <joint name="LLEG_JOINT2" pos="0 0 0" axis="0 1 0" limited="true" range="-2.11843 0.785398" damping="0.2" />
                        <geom pos="0 0 -0.01" type="mesh" mesh="LLEG_LINK2_mesh" />
                        <body name="LLEG_LINK3" pos="0 0 -0.38">
                            <inertial pos="0.0176 0.01611 -0.17992" mass="3.156" diaginertia="0.0592962 0.0592638 0.00799027" />
                            <joint name="LLEG_JOINT3" pos="0 0 0" axis="0 1 0" limited="true" range="0 2.77419" damping="0.2" />
                            <geom pos="0 0 -0.38" type="mesh" mesh="LLEG_LINK3_mesh" />
                            <body name="LLEG_LINK4" pos="0 0 -0.38">
                                <inertial pos="-0.00769 0.00203 -0.00714" quat="0.5 0.5 0.5 0.5" mass="0.836" diaginertia="0.001606 0.00150135 0.0014428" />
                                <joint name="LLEG_JOINT4" pos="0 0 0" axis="0 1 0" limited="true" range="-1.38564 1.47343" damping="0.2" />
                                <geom pos="0 0 -0.38" type="mesh" mesh="LLEG_LINK4_mesh" />
                                <body name="LLEG_LINK5" pos="0 0 -0.04">
                                    <inertial pos="0.00064 0.00264 -0.05633" quat="0.5 0.5 0.5 0.5" mass="1.552" diaginertia="0.00907896 0.00902826 0.00442296" />
                                    <joint name="LLEG_JOINT5" pos="0 0 0" axis="1 0 0" limited="true" range="-1.0472 1.0472" damping="0.2" />
                                    <geom pos="0 0 -0.04" type="mesh" mesh="LLEG_LINK5_mesh" />
                                </body>
                            </body>
                        </body>
                    </body>
                </body>
            </body>
            <body name="RLEG_LINK0" pos="0 -0.1 0.0095">
                <inertial pos="-0.02299 0.00588 -0.07031" quat="0.908703 -0.283036 0.0102762 -0.306665" mass="2.915" diaginertia="0.00999933 0.00999641 0.00998966" />
                <joint name="RLEG_JOINT0" pos="0 0 0" axis="0 0 1" limited="true" range="-1.02662 1.0972" damping="0.2" />
                <geom pos="0 -0.1 0.0095" type="mesh" mesh="RLEG_LINK0_mesh" />
                <body name="RLEG_LINK1" pos="0 0 -0.122">
                    <inertial pos="-0.00441 -0.00696 -0.00694" quat="0.5 0.5 -0.5 0.5" mass="1.199" diaginertia="0.00343603 0.00299879 0.00179963" />
                    <joint name="RLEG_JOINT1" pos="0 0 0" axis="1 0 0" limited="true" range="-0.725029 0.523599" damping="0.2" />
                    <geom pos="0 0 -0.122" type="mesh" mesh="RLEG_LINK1_mesh" />
                    <body name="RLEG_LINK2" pos="0 0 -0.01">
                        <inertial pos="0.00658 -0.03431 -0.18864" quat="0.525016 -0.0126242 -0.0272808 0.850561" mass="5.783" diaginertia="0.110101 0.110013 0.00999652" />
                        <joint name="RLEG_JOINT2" pos="0 0 0" axis="0 1 0" limited="true" range="-2.11843 0.785398" damping="0.2" />
                        <geom pos="0 0 -0.01" type="mesh" mesh="RLEG_LINK2_mesh" />
                        <body name="RLEG_LINK3" pos="0 0 -0.38">
                            <inertial pos="0.0176 -0.01611 -0.17992" mass="3.156" diaginertia="0.0592962 0.0592638 0.00799027" />
                            <joint name="RLEG_JOINT3" pos="0 0 0" axis="0 1 0" limited="true" range="0 2.77419" damping="0.2" />
                            <geom pos="0 0 -0.38" type="mesh" mesh="RLEG_LINK3_mesh" />
                            <body name="RLEG_LINK4" pos="0 0 -0.38">
                                <inertial pos="-0.00769 -0.00203 -0.00714" quat="0.5 0.5 0.5 0.5" mass="0.836" diaginertia="0.001606 0.00150135 0.0014428" />
                                <joint name="RLEG_JOINT4" pos="0 0 0" axis="0 1 0" limited="true" range="-1.38564 1.47343" damping="0.2" />
                                <geom pos="0 0 -0.38" type="mesh" mesh="RLEG_LINK4_mesh" />
                                <body name="RLEG_LINK5" pos="0 0 -0.04">
                                    <inertial pos="0.00064 -0.00264 -0.05633" quat="0.5 0.5 0.5 0.5" mass="1.552" diaginertia="0.00907896 0.00902826 0.00442296" />
                                    <joint name="RLEG_JOINT5" pos="0 0 0" axis="1 0 0" limited="true" range="-1.0472 1.0472" damping="0.2" />
                                    <geom pos="0 0 -0.04" type="mesh" mesh="RLEG_LINK5_mesh" />
                                </body>
                            </body>
                        </body>
                    </body>
                </body>
            </body>
        </body>
    </worldbody>

    <actuator>
        <motor name="CHEST_JOINT0" gear="200" joint="CHEST_JOINT0"/>
        <motor name="CHEST_JOINT1" gear="200" joint="CHEST_JOINT1"/>
        <motor name="CHEST_JOINT2" gear="200" joint="CHEST_JOINT2"/>
        <motor name="HEAD_JOINT0" gear="200" joint="HEAD_JOINT0"/>
        <motor name="HEAD_JOINT1" gear="200" joint="HEAD_JOINT1"/>
        <motor name="LARM_JOINT0" gear="200" joint="LARM_JOINT0"/>
        <motor name="LARM_JOINT1" gear="200" joint="LARM_JOINT1"/>
        <motor name="LARM_JOINT2" gear="200" joint="LARM_JOINT2"/>
        <motor name="LARM_JOINT3" gear="200" joint="LARM_JOINT3"/>
        <motor name="LARM_JOINT4" gear="200" joint="LARM_JOINT4"/>
        <motor name="LARM_JOINT5" gear="200" joint="LARM_JOINT5"/>
        <motor name="LARM_JOINT6" gear="200" joint="LARM_JOINT6"/>
        <motor name="LARM_JOINT7" gear="200" joint="LARM_JOINT7"/>
        <motor name="LARM_F_JOINT0" gear="200" joint="LARM_F_JOINT0"/>       
        <motor name="LARM_F_JOINT1" gear="200" joint="LARM_F_JOINT1"/>
        <motor name="RARM_JOINT0" gear="200" joint="RARM_JOINT0"/>
        <motor name="RARM_JOINT1" gear="200" joint="RARM_JOINT1"/>
        <motor name="RARM_JOINT2" gear="200" joint="RARM_JOINT2"/>
        <motor name="RARM_JOINT3" gear="200" joint="RARM_JOINT3"/>
        <motor name="RARM_JOINT4" gear="200" joint="RARM_JOINT4"/>
        <motor name="RARM_JOINT5" gear="200" joint="RARM_JOINT5"/>
        <motor name="RARM_JOINT6" gear="200" joint="RARM_JOINT6"/>
        <motor name="RARM_JOINT7" gear="200" joint="RARM_JOINT7"/>
        <motor name="RARM_F_JOINT0" gear="200" joint="RARM_F_JOINT0"/>       
        <motor name="RARM_F_JOINT1" gear="200" joint="RARM_F_JOINT1"/>
        <motor name="LLEG_JOINT0" gear="200" joint="LLEG_JOINT0"/>
        <motor name="LLEG_JOINT1" gear="200" joint="LLEG_JOINT1"/>
        <motor name="LLEG_JOINT2" gear="200" joint="LLEG_JOINT2"/>
        <motor name="LLEG_JOINT3" gear="200" joint="LLEG_JOINT3"/>
        <motor name="LLEG_JOINT4" gear="200" joint="LLEG_JOINT4"/>
        <motor name="LLEG_JOINT5" gear="200" joint="LLEG_JOINT5"/>
        <motor name="RLEG_JOINT0" gear="200" joint="RLEG_JOINT0"/>
        <motor name="RLEG_JOINT1" gear="200" joint="RLEG_JOINT1"/>
        <motor name="RLEG_JOINT2" gear="200" joint="RLEG_JOINT2"/>
        <motor name="RLEG_JOINT3" gear="200" joint="RLEG_JOINT3"/>
        <motor name="RLEG_JOINT4" gear="200" joint="RLEG_JOINT4"/>
        <motor name="RLEG_JOINT5" gear="200" joint="RLEG_JOINT5"/>
    </actuator>

</mujoco>
